Workbook

Sheet Summary
A1: Tax / CA Review Pack
A2: Financial year | B2: FY 2025-26
A3: Data covered | B3: Apr 2025 – Mar 2026
A4: Report ID | B4: 2E055FD328
A5: Generated | B5: 05 Oct 2026, 14:02 India Standard Time
A7: Metric | B7: Amount
A8: Salary income | B8: =SUM(Income!B2:B13) -> 2667000
A9: Bonuses | B9: =SUM(Income!C2:C13) -> 180000
A10: Consulting income | B10: =SUM(Income!D2:D13) -> 261000
A11: Other income | B11: =SUM(Income!E2:E13) -> 0
A12: Total income | B12: =SUM(B8:B11) -> 3108000
A13: Spending (excl. investments and debt) | B13: =SUMIF(Expenses!D2:D15,"Spending",Expenses!B2:B15) -> 1370112
A14: Investments (counted as saving) | B14: =SUMIF(Expenses!D2:D15,"Saving",Expenses!B2:B15) -> 380000
A15: Debt repayments | B15: =SUMIF(Expenses!D2:D15,"Debt",Expenses!B2:B15) -> 556232
A16: Savings rate | B16: =IF(B12=0,0,(B12-B13-B15)/B12) -> 0.3801982
A17: Total flagged for CA review | B17: =SUM('Review items'!E2:E69) -> 1202147.1
A18: Total assets | B18: =SUMIF('Balance sheet'!A2:A12,"Asset",'Balance sheet'!C2:C12) -> 7025000
A19: Total liabilities | B19: =SUMIF('Balance sheet'!A2:A12,"Liability",'Balance sheet'!C2:C12) -> 3338000
A20: Net worth | B20: =B18-B19 -> 3687000
A22: Summary of transaction data for review by a qualified professional. Not tax advice.

Sheet Income
A1: Month | B1: Salary | C1: Bonuses | D1: Consulting | E1: Other | F1: Total
A2: Apr 2025 | B2: 214000 | C2: 0 | D2: 23000 | E2: 0 | F2: =SUM(B2:E2) -> 237000
A3: May 2025 | B3: 215500 | C3: 0 | D3: 25500 | E3: 0 | F3: =SUM(B3:E3) -> 241000
A4: Jun 2025 | B4: 217000 | C4: 0 | D4: 18000 | E4: 0 | F4: =SUM(B4:E4) -> 235000
A5: Jul 2025 | B5: 218500 | C5: 0 | D5: 20500 | E5: 0 | F5: =SUM(B5:E5) -> 239000
A6: Aug 2025 | B6: 220000 | C6: 0 | D6: 23000 | E6: 0 | F6: =SUM(B6:E6) -> 243000
A7: Sep 2025 | B7: 221500 | C7: 90000 | D7: 25500 | E7: 0 | F7: =SUM(B7:E7) -> 337000
A8: Oct 2025 | B8: 223000 | C8: 0 | D8: 18000 | E8: 0 | F8: =SUM(B8:E8) -> 241000
A9: Nov 2025 | B9: 224500 | C9: 0 | D9: 20500 | E9: 0 | F9: =SUM(B9:E9) -> 245000
A10: Dec 2025 | B10: 226000 | C10: 0 | D10: 23000 | E10: 0 | F10: =SUM(B10:E10) -> 249000
A11: Jan 2026 | B11: 227500 | C11: 0 | D11: 25500 | E11: 0 | F11: =SUM(B11:E11) -> 253000
A12: Feb 2026 | B12: 229000 | C12: 0 | D12: 18000 | E12: 0 | F12: =SUM(B12:E12) -> 247000
A13: Mar 2026 | B13: 230500 | C13: 90000 | D13: 20500 | E13: 0 | F13: =SUM(B13:E13) -> 341000
A14: Total | B14: =SUM(B2:B13) -> 2667000 | C14: =SUM(C2:C13) -> 180000 | D14: =SUM(D2:D13) -> 261000 | E14: =SUM(E2:E13) -> 0 | F14: =SUM(F2:F13) -> 3108000
A16: Salary credits more than 25% above the fitted base-salary trend are split into base salary (trend) and bonus (excess).

Sheet Expenses
A1: Category | B1: Amount | C1: Transactions | D1: Kind
A2: Housing | B2: 384000 | C2: 12 | D2: Spending
A3: Food | B3: 277488 | C3: 73 | D3: Spending
A4: Shopping | B4: 139840 | C4: 24 | D4: Spending
A5: Transport | B5: 106126 | C5: 54 | D5: Spending
A6: Entertainment | B6: 82635 | C6: 47 | D6: Spending
A7: Travel | B7: 79823 | C7: 3 | D7: Spending
A8: Utilities | B8: 68450 | C8: 35 | D8: Spending
A9: Insurance | B9: 66000 | C9: 12 | D9: Spending
A10: Other | B10: 52216 | C10: 29 | D10: Spending
A11: Education | B11: 50310 | C11: 12 | D11: Spending
A12: Healthcare | B12: 41283 | C12: 11 | D12: Spending
A13: Personal Care | B13: 21941 | C13: 12 | D13: Spending
A14: Investments (counted as saving) | B14: 380000 | D14: Saving
A15: Debt repayments (EMIs, credit card) | B15: 556232 | D15: Debt

Sheet Balance sheet
A1: Section | B1: Item | C1: Value / outstanding | D1: Interest rate | E1: EMI | F1: Next due
A2: Asset | B2: Property | C2: 4200000
A3: Asset | B3: Vehicle | C3: 650000
A4: Asset | B4: Mutual Funds | C4: 625000
A5: Asset | B5: Fixed Deposit | C5: 450000
A6: Asset | B6: Equity Portfolio | C6: 410000
A7: Asset | B7: Savings Account | C7: 325000
A8: Asset | B8: Gold | C8: 280000
A9: Asset | B9: Current Account | C9: 85000
A10: Liability | B10: Credit Card | C10: 68000 | D10: 0.32 | E10: 7000 | F10: 46300
A11: Liability | B11: Car Loan | C11: 420000 | D11: 0.091 | E11: 11200 | F11: 46302
A12: Liability | B12: Home Loan | C12: 2850000 | D12: 0.0835 | E12: 28500 | F12: 46305
A14: Snapshot as of 2026-10-01

Sheet Review items
A1: Item | B1: txn_id | C1: Date | D1: Description | E1: Amount | F1: Note for CA
A2: Health insurance premiums | B2: T0174 | C2: 45757 | D2: Health insurance | E2: 5500 | F2: Possible Sec 80D deduction. Confirm the policy covers self/family/parents and the premium was not paid in cash.
A3: Health insurance premiums | B3: T0203 | C3: 45787 | D3: Health insurance | E3: 5500 | F3: Possible Sec 80D deduction. Confirm the policy covers self/family/parents and the premium was not paid in cash.
A4: Health insurance premiums | B4: T0231 | C4: 45818 | D4: Health insurance | E4: 5500 | F4: Possible Sec 80D deduction. Confirm the policy covers self/family/parents and the premium was not paid in cash.
A5: Health insurance premiums | B5: T0259 | C5: 45848 | D5: Health insurance | E5: 5500 | F5: Possible Sec 80D deduction. Confirm the policy covers self/family/parents and the premium was not paid in cash.
A6: Health insurance premiums | B6: T0288 | C6: 45879 | D6: Health insurance | E6: 5500 | F6: Possible Sec 80D deduction. Confirm the policy covers self/family/parents and the premium was not paid in cash.
A7: Health insurance premiums | B7: T0316 | C7: 45910 | D7: Health insurance | E7: 5500 | F7: Possible Sec 80D deduction. Confirm the policy covers self/family/parents and the premium was not paid in cash.
A8: Health insurance premiums | B8: T0344 | C8: 45940 | D8: Health insurance | E8: 5500 | F8: Possible Sec 80D deduction. Confirm the policy covers self/family/parents and the premium was not paid in cash.
A9: Health insurance premiums | B9: T0372 | C9: 45971 | D9: Health insurance | E9: 5500 | F9: Possible Sec 80D deduction. Confirm the policy covers self/family/parents and the premium was not paid in cash.
A10: Health insurance premiums | B10: T0400 | C10: 46001 | D10: Health insurance | E10: 5500 | F10: Possible Sec 80D deduction. Confirm the policy covers self/family/parents and the premium was not paid in cash.
A11: Health insurance premiums | B11: T0429 | C11: 46032 | D11: Health insurance | E11: 5500 | F11: Possible Sec 80D deduction. Confirm the policy covers self/family/parents and the premium was not paid in cash.
A12: Health insurance premiums | B12: T0457 | C12: 46063 | D12: Health insurance | E12: 5500 | F12: Possible Sec 80D deduction. Confirm the policy covers self/family/parents and the premium was not paid in cash.
A13: Health insurance premiums | B13: T0485 | C13: 46091 | D13: Health insurance | E13: 5500 | F13: Possible Sec 80D deduction. Confirm the policy covers self/family/parents and the premium was not paid in cash.
... A69: Rent / Home Maintenance | B69: T0482 | C69: 46084 | D69: Rent / Home Maintenance | E69: 32000 | F69: Ask: rent (possible HRA/80GG) or maintenance? Relevant because a home loan also exists.
A71: Flagged for review only — no tax has been calculated.

Sheet Ledger
A1: txn_id | B1: Cleaned id | C1: Date | D1: Category | E1: Description | F1: Type | G1: Kind | H1: Amount | I1: Flags
A2: T0703 | B2: T0703 | C2: 45748 | D2: Entertainment | E2: Streaming | F2: expense | G2: spending | H2: 2072.42
A3: T0169 | B3: T0169 | C3: 45749 | D3: Salary | E3: Monthly salary | F3: income | G3: income | H3: 214000
A4: T0171 | B4: T0171 | C4: 45750 | D4: Housing | E4: Rent / Home Maintenance | F4: expense | G4: spending | H4: 32000
A5: T0187 | B5: T0187 | C5: 45751 | D5: Transport | E5: Fuel | F5: expense | G5: spending | H5: 826.47
A6: T0182 | B6: T0182 | C6: 45751 | D6: Food | E6: Groceries | F6: expense | G6: spending | H6: 2968.68
A7: T0170 | B7: T0170 | C7: 45752 | D7: Other Income | E7: Consulting income | F7: income | G7: income | H7: 23000
A8: T0183 | B8: T0183 | C8: 45754 | D8: Food | E8: Supermarket | F8: expense | G8: spending | H8: 4320.54
A9: T0172 | B9: T0172 | C9: 45754 | D9: Debt Payment | E9: Home loan EMI | F9: expense | G9: debt | H9: 28500
A10: T0173 | B10: T0173 | C10: 45755 | D10: Debt Payment | E10: Car loan EMI | F10: expense | G10: debt | H10: 11200
A11: T0174 | B11: T0174 | C11: 45757 | D11: Insurance | E11: Health insurance | F11: expense | G11: spending | H11: 5500
A12: T0775 | B12: T0775 | C12: 45757 | D12: Other | E12: Gifts | F12: expense | G12: spending | H12: 2013.22
A13: T0184 | B13: T0184 | C13: 45757 | D13: Food | E13: Supermarket | F13: expense | G13: spending | H13: 3782.84
... A54: T0218 | B54: T0218 | C54: 45785 | D54: Shopping | E54: Online shopping | F54: expense | G54: spending | H54: 7574.19
A55: T0202 | B55: T0202 | C55: 45785 | D55: Debt Payment | E55: Car loan EMI | F55: expense | G55: debt | H55: 11200 | I55: category_corrected
A56: T0203 | B56: T0203 | C56: 45787 | D56: Insurance | E56: Health insurance | F56: expense | G56: spending | H56: 5500
A57: T0216 | B57: T0216 | C57: 45788 | D57: Transport | E57: Fuel | F57: expense | G57: spending | H57: 2828.36
A58: T0211 | B58: T0211 | C58: 45788 | D58: Food | E58: Groceries | F58: expense | G58: spending | H58: 4522.15
A59: T0204 | B59: T0204 | C59: 45789 | D59: Utilities | E59: Electricity | F59: expense | G59: spending | H59: 3700
A60: T0205 | B60: T0205 | C60: 45790 | D60: Utilities | E60: Internet | F60: expense | G60: spending | H60: 1200
A61: T0212 | B61: T0212 | C61: 45791 | D61: Food | E61: Groceries | F61: expense | G61: spending | H61: 5315.49
A62: T0206 | B62: T0206 | C62: 45791 | D62: Utilities | E62: Mobile | F62: expense | G62: spending | H62: 900
A63: T0776 | B63: T0776 | C63: 45792 | D63: Other | E63: Miscellaneous | F63: expense | G63: spending | H63: 1056.47
A64: T0207 | B64: T0207 | C64: 45792 | D64: Investments | E64: Mutual fund SIP | F64: expense | G64: investment | H64: 20000
A65: T0208 | B65: T0208 | C65: 45793 | D65: Investments | E65: Equity investment | F65: expense | G65: investment | H65: 10000
A66: T0213 | B66: T0213 | C66: 45794 | D66: Food | E66: Groceries | F66: expense | G66: spending | H66: 2035.67
A67: T0728 | B67: T0728 | C67: 45795 | D67: Entertainment | E67: Weekend outing | F67: expense | G67: spending | H67: 1597.96
... A213: T0342 | B213: T0342 | C213: 45937 | D213: Debt Payment | E213: Home loan EMI | F213: expense | G213: debt | H213: 28500
A214: T0343 | B214: T0343 | C214: 45938 | D214: Debt Payment | E214: Car loan EMI | F214: expense | G214: debt | H214: 0 | I214: zero_amount
A215: T0344 | B215: T0344 | C215: 45940 | D215: Insurance | E215: Health insurance | F215: expense | G215: spending | H215: 5500
A216: T0345 | B216: T0345 | C216: 45942 | D216: Utilities | E216: Electricity | F216: expense | G216: spending | H216: 3700
A217: T0346 | B217: T0346 | C217: 45943 | D217: Utilities | E217: Internet | F217: expense | G217: spending | H217: 1200
A218: T0781 | B218: T0781 | C218: 45943 | D218: Transport | E218: Fuel | F218: expense | G218: spending | H218: 1876.65
A219: T0347 | B219: T0347 | C219: 45944 | D219: Utilities | E219: Mobile | F219: expense | G219: spending | H219: 900
A220: T0348 | B220: T0348 | C220: 45945 | D220: Investments | E220: Mutual fund SIP | F220: expense | G220: investment | H220: 20000
A221: T0355 | B221: T0355 | C221: 45946 | D221: Transport | E221: Car maintenance | F221: expense | G221: spending | H221: 1515.46
A222: T0360 | B222: T0360 | C222: 45946 | D222: Entertainment | E222: Streaming | F222: expense | G222: spending | H222: 1896.4
A223: T0364 | B223: T0364 | C223: 45946 | D223: Other | E223: Bank charges | F223: expense | G223: spending | H223: 2359.95
A224: T0365 | B224: T0365 | C224: 45946 | D224: Education | E224: Books | F224: expense | G224: spending | H224: 4540.32
A225: T0358 | B225: T0358 | C225: 45946 | D225: Shopping | E225: Electronics | F225: expense | G225: spending | H225: 6338.03
...

Sheet Quality log
A1: txn_id | B1: Date | C1: Issue | D1: Severity | E1: Decision | F1: Reason / detail | G1: Excluded
A2: T0410 | B2: 46009 | C2: Exact duplicate row | D2: medium | E2: Removed | F2: Food delivery 5007.03 on 2025-12-18 | G2: No
A3: T0760 | B3: 46074 | C3: Duplicate transaction ID (different transactions) | D3: medium | E3: Re-keyed as T0760-B | F3: Movies | G3: No
A4: T0202 | B4: 45785 | C4: Category does not match description | D4: medium | E4: Corrected 'Foods' -> 'Debt Payment' | F4: Car loan EMI | G4: No
A5: T0343 | B5: 45938 | C5: Zero-value payment | D5: medium | E5: Kept; flagged as possible missed payment | F5: Car loan EMI on 2025-10-08 | G5: No
A6: T0488 | B6: 46095 | C6: Extreme outlier (likely data-entry error) | D6: high | E6: Excluded from core metrics (shown in anomalies) | F6: Mobile ₹185,000 vs typical ₹900 (206x) | G6: Yes
